<?xml version="1.0"?>
<robot name="mobile_robot" xmlns:xacro="http://www.ros.org/wiki/xacro">

    <xacro:property name="pi_const" value="3.14159265"/>

    <xacro:property name="a" value="1.1176" />
    <xacro:property name="b" value="0.4572" />
    <xacro:property name="c" value="0.562" />

    <xacro:property name="r" value="0.15875" />
    <xacro:property name="d" value="0.1016" />

    <xacro:property name="s1" value="0.4318" />

    <xacro:property name="s2" value="0.3429" />
    <xacro:property name="s3" value="0.3429" />

    <xacro:property name="s4" value="0.2794" />

    <xacro:property name="m1" value="40.0" />
    <xacro:property name="m2" value="3.0" />


    <xacro:property name="Ix_body" value="${(1/12)*m1*(b*b+c*c)}"/>
    <xacro:property name="Iy_body" value="${(1/12)*m1*(a*a+b*b)}"/>
    <xacro:property name="Iz_body" value="${(1/12)*m1*(a*a+c*c)}"/>

    <xacro:property name="Iz_wheel" value="${0.5*m2*r*r}"/>
    <xacro:property name="I_wheel" value="${(1.0/12.0)*m2*(3.0*r*r+d*d)}"/>

    <xacro:macro name="inertia_body">
        <inertial>
        <origin rpy="0 0 0" xyz="0 0 ${s1}"/>
        <mass value="${m1}"/>
        <inertia ixx="${Ix_body}" ixy="0.0" ixz="0.0" iyy="${Iy_body}" iyz="0" izz="${Iz_body}"/>
        </inertial>
    </xacro:macro>

    <xacro:macro name="inertia_wheel">
        <inertial>
        <origin rpy="1.570795 0 0" xyz="0 0 0"/>
        <mass value="${m2}"/>
        <inertia ixx="${I_wheel}" ixy="0.0" ixz="0.0" iyy="${I_wheel}" iyz="0" izz="${Iz_wheel}"/>
        </inertial>
    </xacro:macro>

    <xacro:include filename="$(find mobile_robot)/model/robot.gazebo"/>

    <link name="base_footprint"> </link>
    <joint name="body_link_joint" type="fixed">
        <parent link="base_footprint"/>
        <child link="body_link"/>
    </joint>

    <link name="body_link">
        <visual>
            <geometry>
                <box size="${a} ${b} ${c}"/>
            </geometry>
        <origin rpy="0 0 0" xyz="0 0 ${s1}"/>
        </visual>
        <collision>
            <geometry>
                <box size="${a} ${c} ${b}"/>
            </geometry>
            <origin rpy="0 0 0" xyz="0 0 ${s1}"/>
        </collision>
        <xacro:inertia_body/>
    </link>

    <joint name="wheel1_joint" type="continuous">
        <parent link="body_link"/>
        <child link="wheel1_link"/>
        <origin xyz="${-s2} ${-s4} ${r}" rpy="0 0 0"/>
        <axis xyz="0 1 0"/>
        <limit effort="50000" velocity="10"/>
        <dynamics damping="1.0" friction="1.0"/>
    </joint>

    <link name="wheel1_link">
        <visual>
            <origin rpy="1.570795 0 0" xyz="0 0 0"/>
            <geometry>
                <cylinder length="${d}" radius="${r}"/>
            </geometry>
        </visual>
        <collision>
            <origin rpy="1.570795 0 0" xyz="0 0 0"/>
            <geometry>
                <cylinder length="${d}" radius="${r}"/>
            </geometry>
        </collision>
        <xacro:inertia_wheel/>
    </link>

    <joint name="wheel2_joint" type="continuous">
        <parent link="body_link"/>
        <child link="wheel2_link"/>
        <origin xyz="${-s2} ${s4} ${r}" rpy="0 0 0"/>
        <axis xyz="0 1 0"/>
        <limit effort="50000" velocity="10"/>
        <dynamics damping="1.0" friction="1.0"/>
    </joint>

    <link name="wheel2_link">
        <visual>
            <origin rpy="1.570795 0 0" xyz="0 0 0"/>
            <geometry>
                <cylinder length="${d}" radius="${r}"/>
            </geometry>
        </visual>
        <collision>
            <origin rpy="1.570795 0 0" xyz="0 0 0"/>
            <geometry>
                <cylinder length="${d}" radius="${r}"/>
            </geometry>
        </collision>
        <xacro:inertia_wheel/>
    </link>

    <xacro:macro name="steering_knuckle" params="prefix x y">
        <joint name="${prefix}_steer_joint" type="revolute">
            <parent link="body_link"/>
            <child link="${prefix}_steer_link"/>
            <origin xyz="${x} ${y} ${r}" rpy="0 0 0"/>
            <axis xyz="0 0 1"/>
            <limit lower="-0.785" upper="0.785" effort="5000" velocity="5.0"/>
            <dynamics damping="0.1" friction="0.1"/>
        </joint>

        <link name="${prefix}_steer_link">
            <inertial>
                <mass value="0.5"/>
                <origin xyz="0 0 0" rpy="0 0 0"/>
                <inertia ixx="0.001" ixy="0" ixz="0" iyy="0.001" iyz="0" izz="0.001"/>
            </inertial>
        </link>

        <joint name="${prefix}_wheel_joint" type="continuous">
            <parent link="${prefix}_steer_link"/>
            <child link="${prefix}_wheel_link"/>
            <origin xyz="0 0 0" rpy="0 0 0"/>
            <axis xyz="0 1 0"/>
            <limit effort="50000" velocity="10"/>
            <dynamics damping="1.0" friction="1.0"/>
        </joint>

        <link name="${prefix}_wheel_link">
            <visual>
                <origin rpy="1.570795 0 0" xyz="0 0 0"/>
                <geometry>
                    <cylinder length="${d}" radius="${r}"/>
                </geometry>
            </visual>
            <collision>
                <origin rpy="1.570795 0 0" xyz="0 0 0"/>
                <geometry>
                    <cylinder length="${d}" radius="${r}"/>
                </geometry>
            </collision>
            <xacro:inertia_wheel/>
        </link>
    </xacro:macro>

    <xacro:steering_knuckle prefix="front_left" x="${s3}" y="${s4}"/>
    <xacro:steering_knuckle prefix="front_right" x="${s3}" y="${-s4}"/>

    <joint name="lidar_joint" type="fixed">
        <origin xyz="0.0 0 ${s1 + (c/2)}" rpy="0 0 0"/>
        <parent link="body_link"/>
        <child link="lidar_link"/>
    </joint>

    <link name="lidar_link">
        <visual>
            <origin xyz="0 0 0.05" rpy="0 0 0"/>
            <geometry>
                <cylinder length="0.1" radius="0.1"/>
            </geometry>
        </visual>
        <collision>
            <origin xyz="0 0 0.05" rpy="0 0 0"/>
            <geometry>
                <cylinder length="0.1" radius="0.1"/>
            </geometry>
        </collision>
        <inertial>
            <mass value="1e-6"/>
            <origin xyz="0 0 0" rpy="0 0 0"/>
            <inertia ixx="1e-6" ixy="0" ixz="0" iyy="1e-6" iyz="0" izz="1e-6"/>
        </inertial>
    </link>

    <link name="imu_link">
        <visual>
            <geometry>
                <box size="0.05 0.05 0.05"/>
            </geometry>
            <material name="black"/>
        </visual>
    </link>

    <joint name="imu_joint" type="fixed">
        <parent link="body_link"/>
        <child link="imu_link"/>
        <origin xyz="0 0 ${s1}" rpy="0 0 0"/> </joint>

</robot>
